Workbook
Name cost_house: [1]土地及房屋建築!$G$11
Name cost_machine: [2]機械設備!$G$16
Name cost_others: [2]雜項設備!$G$13
Name cost_tranport: [2]交通及運輸設備!$G$10
Name depre_house: #REF!
Name depre_house: #REF!
Name depre_house: #REF!
Name depre_house: #REF!
Name depre_machine: #REF!
Name depre_machine: #REF!
Name depre_machine: #REF!
Name depre_others: #REF!
Name depre_others: #REF!
Name depre_others: #REF!
Name depre_software: #REF!
Name depre_software: #REF!
Name depre_software: #REF!
Name depre_transport: #REF!
Name depre_transport: #REF!
Name depre_transport: #REF!
Name machine: [2]機械設備!$K$18
Name new_house: [1]土地及房屋建築!$K$11
Name new_machine: [2]機械設備!$K$16
Name new_others: [2]雜項設備!$K$13
Name new_tranport: [2]交通及運輸設備!$K$10
Name old_house: [1]土地及房屋建築!$K$12
Name old_machine: [2]機械設備!$K$17
Name old_others: [2]雜項設備!$K$14
Name old_tranport: [2]交通及運輸設備!$K$11
Name others: [2]雜項設備!$K$15
Name revenue: [3]總表!$G$5
Name revenue__tax: #REF!
Name revenue__tax: #REF!
Name revenue__tax: #REF!
Name revenue__tax: #REF!
Name revenue_ben: #REF!
Name revenue_ben: #REF!
Name revenue_ben: #REF!
Name revenue_btx: [4]營業收支表!#REF!
Name revenue_btx: [4]營業收支表!#REF!
Name revenue_btx: [4]營業收支表!#REF!
Name revenue_btx: [4]營業收支表!#REF!
Name revenue_ptx: [4]營業收支表!#REF!
Name revenue_ptx: [4]營業收支表!#REF!
Name revenue_ptx: [4]營業收支表!#REF!
Name revenue_ptx: [4]營業收支表!#REF!
Name revenue_tax: #REF!
Name revenue_tax: #REF!
Name revenue_tax: #REF!
Name revenue_tax: #REF!
Name tranport: [2]交通及運輸設備!$K$12
Name 房屋及建築: #REF!
Name 房屋及建築: #REF!
Name 房屋及建築: #REF!
Name 房屋及建築: #REF!

Sheet 金控動支排名
B2: 2025年營業費用
B3: 排序 | C3: 單位 | D3: 年度預算金額(仟元) | E3: 動支率(%)
B4: 1 | C4: 營運管理處 | D4: 96668 | E4: 0.87788714
B5: 2 | C5: 董事長室及祕書處 | D5: 87207 | E5: 0.77292134
B6: 3 | C6: 數位科技處 | D6: 30242 | E6: 0.53567052
B7: 4 | C7: 會計管理組 | D7: 17285.85 | E7: 0.5276223
B8: 5 | C8: 人力資源處 | D8: 338756.2 | E8: 0.51976315
B9: 6 | C9: 風險管理處 | D9: 15390.893 | E9: 0.44162447
B10: 7 | C10: 永續辦公室 | D10: 15550.5 | E10: 0.41747301
B11: 8 | C11: 資訊安全處 | D11: 1100 | E11: 0.37838545
B12: 9 | C12: 總經理辦公室 | D12: 29358 | E12: 0.3584985
B13: 10 | C13: 資訊處 | D13: 4504 | E13: 0.35783215
B14: 11 | C14: 稽核總處 | D14: 2112 | E14: 0.34245597
B15: 12 | C15: 法令遵循處 | D15: 9022 | E15: 0.31717435
B16: 13 | C16: 財務管理處 | D16: 69880 | E16: 0.17503173
D17: =SUBTOTAL(109,表格1_3[年度預算金額(仟元)]) -> 717076.44 | E17: =SUBTOTAL(101,表格1_3[動支率(%)]) -> 0.46325693
D18: 資料日：2025年8月
B23: 數位科技處歷年預算 (仟元)
B24: 年份 | C24: 營業費用 | E24: 資本支出 (資訊) (含筆記型電腦 ) | F24: 備註
C25: 原始金額 | D25: 定案金額
B26: 2026 | C26: =【全處】2026年預算編列!N89 -> 40051.4 | D26: 待核定 | E26: =【全處】2026年預算編列!N97 -> 11520 | F26: 筆記型電腦 $600 機械及設備－伺服器 $6,500 應用軟體 $4,420
B27: 2025 | C27: 43242 | D27: 30242 | E27: 5200 | F27: 營業費用最終 7 折定案
B28: 2024 | C28: =D28/0.8 -> 45183.75 | D28: 36147 | E28: 17500 | F28: 營業費用最終 8 折定案
B29: 2023 | C29: =D29/0.62 -> 44764.516 | D29: 27754 | E29: 25100 | F29: 營業費用最終 62 折定案
B30: 2022 | C30: =D30/0.8 -> 56638.75 | D30: 45311 | E30: 32650 | F30: 營業費用最終 8 折定案
B31: 2021 | C31: 31000 | D31: 31000 | E31: 48031

Sheet 【全處】2026年預算編列
E1: 2025年度 | N1: 2026年度
B2: 2020年費用 | E2: 營業費用 | G2: 年度預算 | I2: ~8月(實際動支) | L2: ~12月(年化動支) | N2: 本次編列
B3: 預算金額(仟元) | C3: 當年動支金額 | D3: 動支率(%) | E3: 費用科目 | G3: 金額(仟元) | H3: % | I3: 動支金額 | J3: 剩餘金額 | K3: 動支率(%) | L3: 動支金額 | M3: 動支率(%) | N3: 金額(仟元) | O3: % | P3: 成長率(%) | Q3: 備註說明
B4: 50 | C4: 22.071 | D4: =C4/B4 -> 0.44142 | E4: 21-100 | F4: 建物維修 | G4: 75 | H4: - | I4: 0 | J4: =G4-I4 -> 75 | K4: =I4/G4 -> 0 | L4: =I4/8*12 -> 0 | M4: =L4/G4 -> 0 | N4: 75 | O4: - | P4: =(N4-G4)/G4 -> 0 | Q4: 依照營管處報價： 1. 消防和公安申報 22,000元+檢修約20,000元=42,000元/年 2. 室內空調維護 : 一次1,500元@20台=30,000元/年 【預期支出】72仟元/年 【屬預防性支出，建議維持2025年預算不變】
B5: 0 | C5: 11.493 | D5: - | E5: 21-201 | F5: 房租支出-保證金折現攤銷 | G5: 8 | H5: - | I5: 17.524 | J5: =G5-I5 -> -9.524 | K5: =I5/G5 -> 2.1905 | L5: =I5+(4.807*4) -> 36.752 | M5: =L5/G5 -> 4.594 | N5: 60 | O5: - | P5: =(N5-G5)/G5 -> 6.5 | Q5: 依照會計處報價： 房租保證金每月攤銷至租約到期，4,807元/月*12月=57,684元/年 【預期支出】58仟元/年
B6: 0 | C6: 0 | D6: - | E6: 21-290 | F6: 房租支出-其他租賃 | G6: - | H6: - | J6: - | K6: - | L6: - | M6: - | N6: - | O6: - | P6: - | Q6: 【將編列於63-100使用權資產折舊-房屋及建築】
B7: 24 | C7: 113.43 | D7: =C7/B7 -> 4.72625 | E7: 21-300 | F7: 電費 | G7: 700 | H7: - | I7: 458.242 | J7: =G7-I7 -> 241.758 | K7: =I7/G7 -> 0.65463143 | L7: =I7+(134.476*4) -> 996.146 | M7: =L7/G7 -> 1.4230657 | N7: 1700 | O7: - | P7: =(N7-G7)/G7 -> 1.4285714 | Q7: 依最高一期電費$134,476(7月)*12 進行編列 【預期支出】1,614仟元/年
B8: 24 | C8: 15.895 | D8: =C8/B8 -> 0.66229167 | E8: 21-310 | F8: 水費 | G8: 25 | H8: - | I8: 10.488 | J8: =G8-I8 -> 14.512 | K8: =I8/G8 -> 0.41952 | L8: =I8+(2.709*4) -> 21.324 | M8: =L8/G8 -> 0.85296 | N8: 33 | O8: - | P8: =(N8-G8)/G8 -> 0.32 | Q8: 依最高一期水費$2,709(7月)*12 進行編列 【預期支出】33仟元/年
B9: 0 | C9: 0 | D9: - | E9: 21-320 | F9: 瓦斯費 | G9: - | H9: - | J9: - | K9: - | L9: - | M9: - | N9: - | O9: - | P9: - | Q9: 【本處無需編列】
B10: 24 | C10: 14.334 | D10: =C10/B10 -> 0.59725 | E10: 21-400 | F10: 保全費 | G10: - | H10: - | J10: - | K10: - | L10: - | M10: - | N10: - | O10: - | P10: - | Q10: 【本處無需編列】
B11: 30 | C11: 75.575 | D11: =C11/B11 -> 2.5191667 | E11: 21-600 | F11: 環境美化及清潔費 | G11: 200 | H11: - | I11: 121.088 | J11: =G11-I11 -> 78.912 | K11: =I11/G11 -> 0.60544 | L11: =I11+(50*4) -> 321.088 | M11: =L11/G11 -> 1.60544 | N11: 600 | O11: - | P11: =(N11-G11)/G11 -> 2 | Q11: 預期支出計算： 1. 室內消毒 : 6,000元/年 2. 清洗地毯 : 10,000元/年 3. 清潔服務費：$46,500元/月(合約固定金額)；558,000元/年 4. 辦公室節慶佈置20,000元 【預期支出】600仟元/年
B12: 24 | C12: 395.865 | D12: =C12/B12 -> 16.494375 | E12: 21-700 | F12: 大樓管理費 | G12: 514 | H12: - | I12: 346.707 | J12: =G12-I12 -> 167.293 | K12: =I12/G12 -> 0.67452724 | L12: =I12+(57*4) -> 574.707 | M12: =L12/G12 -> 1.118107 | N12: 848 | O12: - | P12: =(N12-G12)/G12 -> 0.64980545 | Q12: 依據管委會公告：2026年起調漲大樓管理費，153元/坪→190元/坪，依承租371.83坪，管理費將由56,890元/月→70,647元/月，70,647元*12月=847,764元/年 【預期支出】848仟元/年
B13: 1000 | C13: 53.471 | D13: =C13/B13 -> 0.053471 | E13: 21-900 | F13: 其他場所費用 | G13: 0 | H13: - | I13: 0 | J13: =G13-I13 -> 0 | K13: - | L13: =I13/10*12 -> 0 | M13: - | N13: 0 | O13: - | P13: - | Q13: 【本處無需編列】
B14: =SUM(B4:B13) -> 1176 | C14: =SUM(C4:C13) -> 702.134 | D14: =C14/B14 -> 0.59705272 | E14: 21 | F14: 場所費用 | G14: 1522 | H14: =G14/G89 -> 0.050327359 | I14: =SUM(I4:I13) -> 954.049 | J14: =G14-I14 -> 567.951 | K14: =I14/G14 -> 0.62683903 | L14: =SUM(L4:L13) -> 1950.017 | M14: =L14/G14 -> 1.2812201 | N14: =SUM(N4:N13) -> 3316 | O14: =N14/N89 -> 0.08279361 | P14: =(N14-G14)/G14 -> 1.1787122 | Q14: =N14-G14 -> 1794
B15: 0 | C15: 94.56 | D15: - | E15: 22-100 | F15: 自動化設備軟體費 | G15: - | H15: - | I15: 84 | J15: - | K15: - | L15: =I15/8*12 -> 126 | M15: - | N15: - | O15: - | P15: - | Q15: 【該項編列在自動化設備系統/軟體使用費，必要時再行流用即可】
B16: 20 | C16: 0 | D16: =C16/B16 -> 0 | E16: 22-200 | F16: 自動化設備維修費 | G16: - | H16: - | J16: - | K16: - | L16: =I16/8*12 -> 0 | M16: - | N16: - | O16: - | P16: - | Q16: 【本處無需編列】
B17: 150 | C17: 14.776 | D17: =C17/B17 -> 0.098506667 | E17: 22-400 | F17: 自動化設備用品費 | G17: 30 | H17: - | I17: 1.575 | J17: =G17-I17 -> 28.425 | K17: =I17/G17 -> 0.0525 | L17: =I17/8*12 -> 2.3625 | M17: =L17/G17 -> 0.07875 | N17: 30 | O17: - | P17: =(N17-G17)/G17 -> 0 | Q17: 【建議維持2025年預算】
B18: 300 | C18: 164.679 | D18: =C18/B18 -> 0.54893 | E18: 22-600 | F18: 自動化設備系統/軟體使用費 | G18: 3044 | H18: - | I18: 1298.674 | J18: =G18-I18 -> 1745.326 | K18: =I18/G18 -> 0.42663403 | L18: =【參考用】【各組】2025年預算編列!G14 -> 1923 | M18: =L18/G18 -> 0.63173456 | N18: =【各組】2026年預算編列!E21 -> 3192.4 | O18: - | P18: =(N18-G18)/G18 -> 0.048751643 | Q18: 詳【各組】2026年預算編列
B19: 835 | C19: 613.189 | D19: =C19/B19 -> 0.73435808 | E19: 22-900 | F19: 其他自動化費用 | G19: - | H19: - | J19: - | K19: - | L19: - | M19: - | N19: - | O19: - | P19: - | Q19: 【本處無需編列】
B20: =SUM(B15:B19) -> 1305 | C20: =SUM(C15:C19) -> 887.204 | D20: =C20/B20 -> 0.67984981 | E20: 22 | F20: 自動化設備費用 | G20: 3074 | H20: =G20/G89 -> 0.10164672 | I20: =SUM(I15:I19) -> 1384.249 | J20: =G20-I20 -> 1689.751 | K20: =I20/G20 -> 0.45030872 | L20: =SUM(L15:L19) -> 2051.3625 | M20: =L20/G20 -> 0.66732677 | N20: =SUM(N15:N19) -> 3222.4 | O20: =N20/N89 -> 0.080456613 | P20: =(N20-G20)/G20 -> 0.048275862 | Q20: =N20-G20 -> 148.4
B21: 40 | C21: 15.124 | D21: =C21/B21 -> 0.3781 | E21: 23-100 | F21: 辦公用品 | G21: 80 | H21: - | I21: 2.551 | J21: =G21-I21 -> 77.449 | K21: =I21/G21 -> 0.0318875 | L21: =I21/8*12 -> 3.8265 | M21: =L21/G21 -> 0.04783125 | N21: 80 | O21: - | P21: =(N21-G21)/G21 -> 0 | Q21: 【建議維持2025年預算】
B22: 100 | C22: 15.435 | D22: =C22/B22 -> 0.15435 | E22: 23-200 | F22: 書報雜誌 | G22: - | H22: - | J22: - | K22: - | L22: - | M22: - | N22: - | O22: - | P22: - | Q22: 【本處無需編列】
B23: 150 | C23: 89.444 | D23: =C23/B23 -> 0.59629333 | E23: 23-300 | F23: 雜項購置 | G23: 100 | H23: - | I23: 0 | J23: =G23-I23 -> 100 | K23: =I23/G23 -> 0 | L23: =I23/8*12 -> 0 | M23: =L23/G23 -> 0 | N23: 100 | O23: - | P23: =(N23-G23)/G23 -> 0 | Q23: 【建議維持2025年預算】
B24: 0 | C24: 0 | D24: - | E24: 23-401 | F24: 辦公設備租金-保證金折現攤銷 | G24: - | H24: - | J24: - | K24: - | L24: - | M24: - | N24: - | O24: - | P24: - | Q24: 【本處無需編列】
B25: 0 | C25: 0 | D25: - | E25: 23-402 | F25: 辦公設備租金-短期租賃 | G25: - | H25: - | J25: - | K25: - | L25: - | M25: - | N25: - | O25: - | P25: - | Q25: 【本處無需編列】
B26: 140 | C26: 59.396 | D26: =C26/B26 -> 0.42425714 | E26: 23-403 | F26: 辦公設備租金-低價值租賃 | G26: 80 | H26: - | I26: 39.895 | J26: =G26-I26 -> 40.105 | K26: =I26/G26 -> 0.4986875 | L26: =I26+(8.3*4) -> 73.095 | M26: =L26/G26 -> 0.9136875 | N26: 99 | O26: - | P26: =(N26-G26)/G26 -> 0.2375 | Q26: 【根據營運管理處盧玟卉提供之費用分攤總表(租金4,300+114/07計張費3,905)推估】事務機租賃費(2台)、計張印刷費(A4 黑白 0.35元/張、彩色 4元)；8,205元*12月=98,460元/年 【預期支出】99仟元/年
B27: 0 | C27: 0 | D27: - | E27: 23-404 | F27: 辦公設備租金-變動租賃 | G27: - | H27: - | J27: - | K27: - | L27: - | M27: - | N27: - | O27: - | P27: - | Q27: 【本處無需編列】
B28: 0 | C28: 0 | D28: - | E28: 23-490 | F28: 辦公設備租金-其他租賃 | G28: - | H28: - | J28: - | K28: - | L28: - | M28: - | N28: - | O28: - | P28: - | Q28: 【本處無需編列】
B29: 30 | C29: 8.762 | D29: =C29/B29 -> 0.29206667 | E29: 23-500 | F29: 印刷費 | G29: 50 | H29: - | I29: 18.307 | J29: =G29-I29 -> 31.693 | K29: =I29/G29 -> 0.36614 | L29: =I29/8*12 -> 27.4605 | M29: =L29/G29 -> 0.54921 | N29: 50 | O29: - | P29: =(N29-G29)/G29 -> 0 | Q29: 【建議維持2025年預算】
B30: 0 | C30: 0 | D30: - | E30: 23-600 | F30: 員工服裝費 | G30: - | H30: - | J30: - | K30: - | L30: - | M30: - | N30: - | O30: - | P30: - | Q30: 【本處無需編列】
B31: 40 | C31: 33.267 | D31: =C31/B31 -> 0.831675 | E31: 23-700 | F31: 辦公設備修護 | G31: 100 | H31: - | I31: 60.054 | J31: =G31-I31 -> 39.946 | K31: =I31/G31 -> 0.60054 | L31: =I31/8*12 -> 90.081 | M31: =L31/G31 -> 0.90081 | N31: 125 | O31: - | P31: =(N31-G31)/G31 -> 0.25 | Q31: 【根據營運管理處盧玟卉提供之費用分攤總表(6月)推估】 UPS不斷電設備維護費24,000元/年；交換機系統維護費99,000元/年。 【預期支出】123仟元/年
B32: 40 | C32: 6.356 | D32: =C32/B32 -> 0.1589 | E32: 23-900 | F32: 其他辦公費用 | G32: 80 | H32: - | I32: 45.254 | J32: =G32-I32 -> 34.746 | K32: =I32/G32 -> 0.565675 | L32: =I32/8*12 -> 67.881 | M32: =L32/G32 -> 0.8485125 | N32: 80 | O32: - | P32: =(N32-G32)/G32 -> 0 | Q32: 【建議維持2025年預算】
B33: =SUM(B21:B32) -> 540 | C33: =SUM(C21:C32) -> 227.784 | D33: =C33/B33 -> 0.42182222 | E33: 23 | F33: 辦公費用 | G33: 490 | H33: =G33/G89 -> 0.016202632 | I33: =SUM(I21:I32) -> 166.061 | J33: =G33-I33 -> 323.939 | K33: =I33/G33 -> 0.3389 | L33: =SUM(L21:L32) -> 262.344 | M33: =L33/G33 -> 0.53539592 | N33: =SUM(N21:N32) -> 534 | O33: =N33/N89 -> 0.013332867 | P33: =(N33-G33)/G33 -> 0.089795918 | Q33: =N33-G33 -> 44
B34: 100 | C34: 69.797 | D34: =C34/B34 -> 0.69797 | E34: 24-100 | F34: 電話費 | G34: 100 | H34: - | I34: 59.975 | J34: =G34-I34 -> 40.025 | K34: =I34/G34 -> 0.59975 | L34: =I34+(12.5*4) -> 109.975 | M34: =L34/G34 -> 1.09975 | N34: 150 | O34: - | P34: =(N34-G34)/G34 -> 0.5 | Q34: 【根據營運管理處盧玟卉提供之費用分攤總表(8月)推估】 12,411元*12月=148,932元/年 【預期支出】149仟元/年
B35: 60 | C35: 48.076 | D35: =C35/B35 -> 0.80126667 | E35: 24-200 | F35: 網路通訊費 | G35: 600 | H35: - | I35: 390.76 | J35: =G35-I35 -> 209.24 | K35: =I35/G35 -> 0.65126667 | L35: =I35+(75*4) -> 690.76 | M35: =L35/G35 -> 1.1512667 | N35: 905 | O35: - | P35: =(N35-G35)/G35 -> 0.50833333 | Q35: 【根據營運管理處盧玟卉提供之費用分攤總表(8月)推估】 75,030元*12月=900,360元/年 【預期支出】901仟元/年
B36: 10 | C36: 4.481 | D36: =C36/B36 -> 0.4481 | E36: 24-500 | F36: 快遞費 | G36: 20 | H36: - | I36: 2.438 | J36: =G36-I36 -> 17.562 | K36: =I36/G36 -> 0.1219 | L36: =I36/8*12 -> 3.657 | M36: =L36/G36 -> 0.18285 | N36: 20 | O36: - | P36: =(N36-G36)/G36 -> 0 | Q36: 【建議維持2025年預算】
B37: 5 | C37: 0 | D37: =C37/B37 -> 0 | E37: 24-600 | F37: 郵資 | G37: 5 | H37: - | I37: 0 | J37: =G37-I37 -> 5 | K37: =I37/G37 -> 0 | L37: =I37/8*12 -> 0 | M37: =L37/G37 -> 0 | N37: 5 | O37: - | P37: =(N37-G37)/G37 -> 0 | Q37: 【建議維持2025年預算】
B38: 0 | C38: 0 | D38: 0 | E38: 24-900 | F38: 其他通訊費用 | G38: 100 | H38: - | I38: 0 | J38: =G38-I38 -> 100 | K38: =I38/G38 -> 0 | L38: =I38/8*12 -> 0 | M38: =L38/G38 -> 0 | N38: 100 | O38: - | P38: - | Q38: 【本處無需編列】
B39: =SUM(B34:B38) -> 175 | C39: =SUM(C34:C38) -> 122.354 | D39: =C39/B39 -> 0.69916571 | E39: 24 | F39: 通訊費用 | G39: 825 | H39: =G39/G89 -> 0.027279942 | I39: =SUM(I34:I38) -> 453.173 | J39: =G39-I39 -> 371.827 | K39: =I39/G39 -> 0.54930061 | L39: =SUM(L34:L38) -> 804.392 | M39: =L39/G39 -> 0.97502061 | N39: =SUM(N34:N38) -> 1180 | O39: =N39/N89 -> 0.029462141 | P39: =(N39-G39)/G39 -> 0.43030303 | Q39: =N39-G39 -> 355
B40: 400 | C40: 0 | D40: =C40/B40 -> 0 | E40: 31-100 | F40: 國內差旅費 | G40: 630 | H40: - | I40: 0 | J40: =G40-I40 -> 630 | K40: =I40/G40 -> 0 | L40: =I40/8*12 -> 0 | M40: =L40/G40 -> 0 | N40: 630 | O40: - | P40: =(N40-G40)/G40 -> 0 | Q40: 【建議維持2025年預算】
...

Sheet 【各組】2026年預算編列
A2: 營 業 費 用 | B2: 22 | C2: 自動化設備費用－自動化設備系統/軟體使用費 | E2: 預算 (仟元) | F2: 組別/成員 | G2: 最低可接受預算 (仟元) | H2: Q1 | I2: Q2 | J2: Q3 | K2: Q4 | L2: 備註 (編列邏輯說明)
C3: 1 | D3: 《軟體訂閱》Notion 專案開發共筆軟體 (每單位8仟元/年，共3單位) | E3: =8*3 -> 24 | F3: AI組/易瑩 | G3: =8*3 -> 24
C4: 2 | D4: 《軟體訂閱》Chat GPT Pro (每單位72仟元/年，共1單位) | E4: =72*1 -> 72 | F4: AI組/易瑩 | G4: =72*1 -> 72
C5: 3 | D5: 《軟體訂閱》Perplexity (每單位7.2仟元/年，共1單位) NEW | E5: =7.2*1 -> 7.2 | F5: AI組/易瑩 | G5: =7.2*1 -> 7.2
C6: 4 | D6: 《軟體訂閱》Claude Pro (每單位7.2仟元/年，共1單位) | E6: =7.2*1 -> 7.2 | F6: AI組/易瑩 | G6: =7.2*1 -> 7.2
C7: 5 | D7: 《軟體訂閱》AI 工具儲值額度 (每單位50仟元/年，共2單位) NEW | E7: 100 | F7: AI組/易瑩 | G7: 100 | L7: 包含科發組雋凱增加1單位
C8: 6 | D8: 《軟體訂閱》Figma (每單位8仟元/年，共2單位) NEW | E8: =8*2 -> 16 | F8: AI組/易瑩 | G8: =8*2 -> 16
C9: 7 | D9: 《軟體訂閱》Github Copilot (每單位18仟元/年，共40單位) NEW | E9: =18*40 -> 720 | F9: AI組/易瑩 | G9: =18*40 -> 720 | L9: IT 仍在內部討論讓各單位支付的可行性，因此建議可先編列
C10: 8 | D10: 《軟體訂閱》Tableau 授權 (Creator 4套 + Explorer 2套 + Viewer 42套 + DM) | E10: 555 | F10: 數據組/Justin | G10: (Min 534仟元)年度憑證 | L10: 依實際(10月)使用情形預估續約授權種類，預留2萬彈性
C11: 9 | D11: 《軟體訂閱》Firecrawl (每單位32仟元/年，共1單位) NEW | E11: 32 | F11: 科發組/雋凱 | G11: 32
C12: 10 | D12: 《軟體訂閱》RSS.app (每單位10仟元/年，共1單位) NEW | E12: 10 | F12: 科發組/雋凱 | G12: 10
C13: 11 | D13: 《維護服務》金控統籌資料共享專案_自然人線上案_金控分攤 | E13: 11 | F13: 策略組/琪鈺 | G13: 11 | L13: 簽呈(202505.01054) 金控2026年及2027年各支付$11
C14: 12 | D14: 《維護服務》Tableau 視覺化平台 | E14: 101 | F14: 數據組/Justin | G14: (Min 101仟元)平台固定維護 | L14: 站台操作技術諮詢服務8人天，費用較2025年減少$240
C15: 13 | D15: 《維護服務》爬蟲館 | E15: 283 | F15: 數據組/Justin | G15: (Min 283仟元)平台固定維護 | L15: 2026/2月優化案保固期滿，收取維護費
C16: 14 | D16: 《維護服務》金控資料資產管理平台 | E16: 504 | F16: 數據組/Justin | G16: (Min 504仟元)平台固定維護 | L16: 年度維護費
C17: 15 | D17: 《雲端服務租用》AWS/GCP/Azure_一般使用 | E17: 450 | F17: 數據組/Justin | G17: (Min 360仟元)維持營運 | L17: 爬蟲館雲端服務依實際費用支付，每月約3萬，預留增加資料流量
C18: 16 | D18: 《雲端服務租用》AWS/GCP/Azure_實驗使用 | E18: 300 | F18: 科發組/雋凱 | G18: 120
C19: 17 | D19: 《雲端服務租用》數位科技聲量監測 NEW | E19: 0 | F19: 科發組/Yvon | G19: 600
E21: =SUM(E3:E20) -> 3192.4 | F21: =E21-[5]【參考用】【各組】2025年預算編列!E14 -> 148.7
B22: 41 | C22: 業務推廣費－媒體廣告費 | E22: 預算 (仟元) | F22: 組別/成員 | G22: 最低可接受預算 (仟元) | H22: Q1 | I22: Q2 | J22: Q3 | K22: Q4 | L22: 備註 (編列邏輯說明)
C23: 1 | D23: 《活動舉辦》2026年台北金融科技展 | E23: 2000 | F23: 科發組/立夫 | G23: 1680 | L23: 參考2025年活動舉辦費用
C24: 2 | D24: 《活動舉辦》2026年永豐科技年會 NEW | E24: 0 | F24: 科發組/立夫 | G24: 2000
C25: 3 | D25: 《活動協辦》金融科技產業聯盟_工作圈專案參與 NEW | E25: 500 | F25: 策略組/婉婷 | G25: 350 | L25: 金/銀/證平均分攤各$350
C26: 4 | D26: 《活動協辦》AI 年會 (外部) NEW | E26: 200 | F26: 科發組/立夫 | G26: 100
C27: 5 | D27: 《活動協辦》生成式 AI 年會 (外部) NEW | E27: 200 | F27: 科發組/立夫 | G27: 100
E29: =SUM(E23:E27) -> 2900 | F29: =E29-[5]【參考用】【各組】2025年預算編列!E20 -> -1130
B30: 51 | C30: 專業服務費用－顧問費 | E30: 預算 (仟元) | F30: 組別/成員 | G30: 最低可接受預算 (仟元) | H30: Q1 | I30: Q2 | J30: Q3 | K30: Q4 | L30: 備註 (編列邏輯說明)
C31: 1 | D31: 《顧問服務》2026 S3策略_金控整合設計卓越中心 | E31: 2000 | F31: 策略組/Matt | G31: 3000
C32: 2 | D32: 《顧問服務》2026 AI發展策略藍圖落地 NEW | E32: 2000 | F32: 策略組/燕茹 | G32: 2000
E34: =SUM(E31:E33) -> 4000 | F34: =E34-[5]【參考用】【各組】2025年預算編列!E24 -> 1000
C35: 專業服務費用－其他專業服務費 | E35: 預算 (仟元) | F35: 組別/成員 | G35: 最低可接受預算 (仟元) | H35: Q1 | I35: Q2 | J35: Q3 | K35: Q4 | L35: 備註 (編列邏輯說明)
C36: 1 | D36: 《產學合作》東吳數金中心 | E36: 750 | F36: 策略組/泳晞 | G36: 500
C37: 2 | D37: 《產學合作》政大商業競賽 | E37: 500 | F37: 策略組/Oliver | G37: 300
C38: 3 | D38: 《產學合作》成大實驗室 | E38: 300 | F38: AI組/易瑩 | G38: 300
C39: 4 | D39: 《產學合作》澳洲大學+台灣大學_AI 賦能量表 NEW | E39: 1300 | F39: AI組/易瑩 | G39: 1500
C40: 5 | D40: 《產學合作》MIT 美國麻省理工學院 NEW | E40: 0 | F40: AI組/易瑩 | G40: 10000 | L40: 定案時將主動請示財務長支應
C41: 6 | D41: 《資料源訂閱》Cmoney 資料採購 | E41: 180 | F41: AI組/易瑩 | G41: 180 | L41: 每年訂閱費
C42: 7 | D42: 《資料源訂閱》爬蟲館資料採購費用 | E42: 654 | F42: 數據組/Justin | G42: 480 | L42: 大數即時輿情及爬蟲資料年度合約$654, 實際約$480
C43: 8 | D43: 《共用》專利申請費用 | E43: 300 | F43: 策略組/玉書 | G43: 200 | L43: 專利：已取得(6項)+申請中(1項)剩餘預算尚可支應；預計申請(5項)按分攤原則編列
C44: 9 | D44: 《共用》會計師合理價格意見書 | E44: 100 | F44: 策略組/燕茹 | G44: 100
...

Sheet 【參考用】【各組】2025年預算編列
A2: 營 業 費 用 | B2: 22 | C2: 自動化設備費用－自動化設備系統/軟體使用費 | E2: 預算 (仟元) | F2: 組別/成員 | G2: 截至2025年12月使用金額 | H2: Q1 | I2: Q2 | J2: Q3 | K2: Q4 | L2: 備註 (編列邏輯說明)
C3: 1 | D3: 《軟體訂閱》Tableau 授權 (Creator 6套 + Explorer 2套 + Viewer 48套 + DM) | E3: 687 | F3: 數據組/Justin | G3: 632 | L3: 依實際使用情形預估授權種類，總費用較24年降低48萬
C4: 2 | D4: 《軟體訂閱》Notion 專案開發共筆軟體 (每單位8仟元/年，共3單位) | E4: 24 | F4: AI組/易瑩 | G4: 24
C5: 3 | D5: 《軟體訂閱》Chat GPT Plus (每單位7.7仟元/年，共1單位) | E5: 7.7 | F5: AI組/易瑩 | G5: 72
C6: 4 | D6: 《軟體訂閱》MidJourney Pro (每單位24仟元/年，共1單位) | E6: 24 | F6: AI組/易瑩 | G6: 0
C7: 5 | D7: 《維護服務》Tableau 視覺化平台 | E7: 341 | F7: 數據組/Justin | G7: 341 | L7: 增加站台操作技術諮詢服務7人天，費用較24年增加11萬
C8: 6 | D8: 《維護服務》爬蟲館 | E8: 236 | F8: 科發組/Justin | G8: 0 | L8: 2025/6月保固期滿，收取維護費
C9: 7 | D9: 《維護服務》金控資料資產管理平台 NEW | E9: 504 | F9: 數據組/Justin | G9: 504 | L9: 2025/4月保固期滿，收取維護費
C10: 8 | D10: 《維護服務》金控統籌資料共享專案_自然人線上案_金控分攤 NEW | E10: 20 | F10: 策略組/Matt | G10: 0 | L10: 《自然人_線上案》全案維護費用 約$12萬元(維護+定期源碼、弱掃、第三方人力)
C11: 9 | D11: 《雲端服務租用》AWS/GCP/Azure_一般使用 | E11: 900 | F11: 科發組/Justin | G11: 350 | L11: 實支實付，平均$30/月預計規劃數位幕僚使用$400
C12: 10 | D12: 《雲端服務租用》AWS/GCP/Azure_實驗使用 | E12: 300 | F12: AI組/易瑩 | G12: 0 | L12: 雲端費用之金額與是否編列於數科處待定，詢問資訊處中，尚待回覆
E14: =SUM(E3:E13) -> 3043.7 | G14: =SUM(G3:G12) -> 1923
B15: 41 | C15: 業務推廣費－媒體廣告費 | E15: 預算 (仟元) | F15: 組別/成員 | G15: 截至2025年12月使用金額 | H15: Q1 | I15: Q2 | J15: Q3 | K15: Q4 | L15: 備註 (編列邏輯說明)
C16: 1 | D16: 《活動舉辦》2025 台北國際金融博覽會 | E16: 1000 | F16: 策略組/倚婷 | G16: 1630
C17: 2 | D17: 《活動舉辦》AI 技術主題競賽 | E17: 3000 | F17: 策略組/Oliver | G17: 1950
C18: 3 | D18: 《活動舉辦》RPA焦點小組研究會 NEW | E18: 30 | F18: 策略組/Heather | G18: 0 | L18: 場地費 8,000 x 2日=16,000+雜費 300*48 人= 14,400
E20: =SUM(E16:E18) -> 4030 | G20: =SUM(G16:G19) -> 3580
B21: 51 | C21: 專業服務費用－顧問費 | E21: 預算 (仟元) | F21: 組別/成員 | G21: 截至2025年12月使用金額 | H21: Q1 | I21: Q2 | J21: Q3 | K21: Q4 | L21: 備註 (編列邏輯說明)
C22: 1 | D22: 《顧問服務》2025 S3策略_金控整合設計卓越中心 NEW | E22: 3000 | F22: 策略組/Matt | G22: 25 | L22: 分享會餐會(4場次)
E24: =SUM(E22:E22) -> 3000 | G24: =SUM(G22:G23) -> 25
C25: 專業服務費用－其他專業服務費 | E25: 預算 (仟元) | F25: 組別/成員 | G25: 截至2025年12月使用金額 | H25: Q1 | I25: Q2 | J25: Q3 | K25: Q4 | L25: 備註 (編列邏輯說明)
C26: 1 | D26: 《產學合作》東吳數金中心 | E26: 750 | F26: 策略組/泳晞 | G26: 500 | L26: 另預計流用$300至「91-200 公會會費」支應「金融科技產業聯盟」會員
C27: 2 | D27: 《產學合作》政大商業競賽 | E27: 500 | F27: 策略組/Oliver | G27: 250
C28: 3 | D28: 《產學合作》MIT 美國麻省理工學院 NEW | E28: 0 | F28: AI組/易瑩 | G28: 0 | L28: 朱總指示與 MIT 教授合作10,000(仟元)，如遇發生再行流用
C29: 4 | D29: 《產學合作》成大實驗室 | E29: 600 | F29: AI組/易瑩 | G29: 600
C30: 5 | D30: 《資料源訂閱》Cmoney 資料採購 | E30: 550 | F30: AI組/易瑩 | G30: 180 | L30: 每年訂閱費+地端建置費 (但最終地端沒有建)
C31: 6 | D31: 《資料源訂閱》爬蟲館資料採購費用 | E31: 520 | F31: 科發組/Justin | G31: 482 | L31: 大數年度合約520K, 實際約250K
C32: 7 | D32: 《共用》專利申請費用 | E32: 300 | F32: 策略組/玉書 | G32: 10
C33: 8 | D33: 《共用》會計師合理價格意見書 | E33: 100 | F33: 策略組/燕茹 | G33: 0
E35: =SUM(E26:E34) -> 3320 | G35: =SUM(G26:G34) -> 2022
B36: 總計 | E36: =SUM(E14,E20,E24,E35) -> 13393.7 | G36: =SUM(G14,G20,G24,G35) -> 7550 | H36: =SUM(H27,H35) -> 0 | I36: =SUM(I27,I35) -> 0 | J36: =SUM(J27,J35) -> 0 | K36: =SUM(K27,K35) -> 0
D38: 資本支出 (編列於資訊處)
B39: 機械 及設備 | C39: 機械及設備－伺服器 | E39: 預算 (仟元) | F39: 組別/成員 | G39: 截至2025年12月使用金額 | H39: Q1 | I39: Q2 | J39: Q3 | K39: Q4 | L39: 備註 (編列邏輯說明)
A40: 資本支出 | C40: 1 | D40: 筆記型電腦 | E40: 600 | F40: 策略組/燕茹 | G40: 655 | L40: 該項預算編列時，直接提報予資訊處數量，並未單一列示
E42: =SUM(E41) -> 0 | G42: =SUM(G40:G41) -> 655
B43: 電腦 軟體 | C43: 電腦軟體－應用軟體 | E43: 預算 (仟元) | F43: 組別/成員 | G43: 截至2025年12月使用金額 | H43: Q1 | I43: Q2 | J43: Q3 | K43: Q4 | L43: 備註 (編列邏輯說明)
C44: 1 | D44: 資料資產管理平台擴增需求 (人力) | E44: 1500 | F44: 數據組/Justin | G44: 1070 | L44: 8,800 x 170人天
C45: 2 | D45: Pentaho工具ETL作業優化 (人力) NEW | E45: 492 | F45: 數據組/Justin | G45: 0 | L45: 8,200 x 60人天
C46: 3 | D46: 爬蟲館平台功能修改費用 (人力) | E46: 648 | F46: 數據組/Justin | L46: 5,400 x 120人天
C47: 4 | D47: Tableau Server平台自動化進階功能 (人力) | E47: 1260 | F47: 數據組/Justin | G47: 882 | L47: 12,600 x 100人天
...

Sheet 【參考用】簽呈202503.08653續約附件六

Sheet 【預算刪減】試算邏輯
B1: 2024年度數位科技處預算刪減試算
B2: 版 本 一 | M2: 原始預算 | O2: 約82折 | P2: 差異值
K3: 22 | L3: 自動化設備費用－自動化設備系統/軟體使用費 | M3: =#REF! -> #REF! | N3: Ú | O3: =M3*0.82 -> #REF! | P3: =O3-M3 -> #REF!
C4: 原始預算 | E4: 折數 | G4: 刪減後 | I4: 差額 | K4: 41 | L4: 業務推廣費－媒體廣告費 | M4: =#REF! -> #REF! | N4: Ú | O4: =M4*0.82 -> #REF! | P4: =O4-M4 -> #REF!
C5: 44826 | D5: Ú | E5: 9折 | F5: Ú | G5: =C5*0.9 -> 40343.4 | I5: =G5-C5 -> -4482.6 | L5: 業務推廣費－專案推廣費 | M5: =#REF! -> #REF! | N5: Ú | O5: =M5*0.82 -> #REF! | P5: =O5-M5 -> #REF!
K6: 51 | L6: 專業服務費用－顧問費 | M6: =#REF! -> #REF! | N6: Ú | O6: =M6*0.82 -> #REF! | P6: =O6-M6 -> #REF!
L7: 專業服務費用－其他專業服務費 | M7: =#REF! -> #REF! | N7: Ú | O7: =M7*0.82 -> #REF! | P7: =O7-M7 -> #REF!
K8: 小計 | M8: =SUM(M3:M7) -> #REF! | N8: Ú | O8: =SUM(O3:O7) -> #REF! | P8: =O8-M8 -> #REF!
B10: 版 本 二 | M10: 原始預算 | O10: 約64折 | P10: 差異值
K11: 22 | L11: 自動化設備費用－自動化設備系統/軟體使用費 | M11: =#REF! -> #REF! | N11: Ú | O11: =M11*0.64 -> #REF! | P11: =O11-M11 -> #REF!
C12: 原始預算 | E12: 折數 | G12: 刪減後 | I12: 差額 | K12: 41 | L12: 業務推廣費－媒體廣告費 | M12: =#REF! -> #REF! | N12: Ú | O12: =M12*0.64 -> #REF! | P12: =O12-M12 -> #REF!
C13: 44826 | D13: Ú | E13: 8折 | F13: Ú | G13: =C13*0.8 -> 35860.8 | I13: =G13-C13 -> -8965.2 | L13: 業務推廣費－專案推廣費 | M13: =#REF! -> #REF! | N13: Ú | O13: =M13*0.64 -> #REF! | P13: =O13-M13 -> #REF!
K14: 51 | L14: 專業服務費用－顧問費 | M14: =#REF! -> #REF! | N14: Ú | O14: =M14*0.64 -> #REF! | P14: =O14-M14 -> #REF!
L15: 專業服務費用－其他專業服務費 | M15: =#REF! -> #REF! | N15: Ú | O15: =M15*0.64 -> #REF! | P15: =O15-M15 -> #REF!
K16: 小計 | M16: =SUM(M11:M15) -> #REF! | N16: Ú | O16: =SUM(O11:O15) -> #REF! | P16: =O16-M16 -> #REF!
B18: 版 本 三 | M18: 原始預算 | O18: 約46折 | P18: 差異值
K19: 22 | L19: 自動化設備費用－自動化設備系統/軟體使用費 | M19: =#REF! -> #REF! | N19: Ú | O19: =M19*0.46 -> #REF! | P19: =O19-M19 -> #REF!
C20: 原始預算 | E20: 折數 | G20: 刪減後 | I20: 差額 | K20: 41 | L20: 業務推廣費－媒體廣告費 | M20: =#REF! -> #REF! | N20: Ú | O20: =M20*0.46 -> #REF! | P20: =O20-M20 -> #REF!
C21: 44826 | D21: Ú | E21: 7折 | F21: Ú | G21: =C21*0.7 -> 31378.2 | I21: =G21-C21 -> -13447.8 | L21: 業務推廣費－專案推廣費 | M21: =#REF! -> #REF! | N21: Ú | O21: =M21*0.46 -> #REF! | P21: =O21-M21 -> #REF!
K22: 51 | L22: 專業服務費用－顧問費 | M22: =#REF! -> #REF! | N22: Ú | O22: =M22*0.46 -> #REF! | P22: =O22-M22 -> #REF!
L23: 專業服務費用－其他專業服務費 | M23: =#REF! -> #REF! | N23: Ú | O23: =M23*0.46 -> #REF! | P23: =O23-M23 -> #REF!
K24: 小計 | M24: =SUM(M19:M23) -> #REF! | N24: Ú | O24: =M24*0.46 -> #REF! | P24: =O24-M24 -> #REF!
B26: 版 本 四 | M26: 原始預算 | O26: 約6折 | P26: 差異值
K27: 22 | L27: 自動化設備費用－自動化設備系統/軟體使用費 | M27: 4961 | N27: Ú | O27: 3661 | P27: =O27-M27 -> -1300
C28: 原始預算 | E28: 折數 | G28: 刪減後 | I28: 差額 | K28: 41 | L28: 業務推廣費－媒體廣告費 | M28: 3800 | N28: Ú | O28: 1800 | P28: =O28-M28 -> -2000
C29: 44826 | D29: Ú | E29: 78折 | F29: Ú | G29: =C29*0.77468 -> 34725.806 | I29: =G29-C29 -> -10100.194 | L29: 業務推廣費－專案推廣費 | M29: 7300 | N29: Ú | O29: 4800 | P29: =O29-M29 -> -2500
K30: 51 | L30: 專業服務費用－顧問費 | M30: 3000 | N30: Ú | O30: 3000 | P30: =O30-M30 -> 0
L31: 專業服務費用－其他專業服務費 | M31: 6100 | N31: Ú | O31: 1800 | P31: =O31-M31 -> -4300
K32: 小計 | M32: 25161 | N32: Ú | O32: =SUM(O27:O31) -> 15061 | P32: =SUM(P27:P31) -> -10100
B35: 版 本 五 | M35: 11.07組長會議決議預算 | O35: 調整後預算 | P35: 差異值
K36: 22 | L36: 自動化設備費用－自動化設備系統/軟體使用費 | M36: 3661 | N36: Ú | O36: =M36*0.5371 -> 1966.3231 | P36: =O36-M36 -> -1694.6769
A37: 最新 | C37: 原始預算 | E37: 折數 | G37: 刪減後 | I37: 差額 | K37: 41 | L37: 業務推廣費－媒體廣告費 | M37: 1800 | N37: Ú | O37: =M37*0.5371 -> 966.78 | P37: =O37-M37 -> -833.22
C38: 44826 | D38: Ú | E38: 62折 | F38: Ú | G38: =C38*0.6191496 -> 27754 | I38: =G38-C38 -> -17072 | L38: 業務推廣費－專案推廣費 | M38: 4800 | N38: Ú | O38: =M38*0.5371+600 -> 3178.08 | P38: =O38-M38 -> -1621.92 | Q38: 含$600國內交際費調整
K39: 51 | L39: 專業服務費用－顧問費 | M39: 3000 | N39: Ú | O39: =M39*0.5371 -> 1611.3 | P39: =O39-M39 -> -1388.7
L40: 專業服務費用－其他專業服務費 | M40: 1800 | N40: Ú | O40: =M40*0.5371 -> 966.78 | P40: =O40-M40 -> -833.22
K41: 小計 | M41: =SUM(M36:M40) -> 15061 | N41: Ú | O41: =SUM(O36:O40) -> 8689.2631 | P41: =SUM(P36:P40) -> -6371.7369

Sheet 【分攤比例】202106.01438
